2023-03-25 12:52:01,757 - telegram.ext._application - INFO - Application started
2023-03-25 12:52:05,922 - telegram.ext._updater - ERROR - Error while getting Updates: Conflict: terminated by other getUpdates request; make sure that only one bot instance is running
2023-03-25 12:52:05,922 - telegram.ext._application - ERROR - No error handlers are registered, logging exception.
Traceback (most recent call last):
  File "/home/VMmanager/.local/lib/python3.8/site-packages/telegram/ext/_updater.py", line 607, in _network_loop_retry
    if not await action_cb():
  File "/home/VMmanager/.local/lib/python3.8/site-packages/telegram/ext/_updater.py", line 335, in polling_action_cb
    raise exc
  File "/home/VMmanager/.local/lib/python3.8/site-packages/telegram/ext/_updater.py", line 320, in polling_action_cb
    updates = await self.bot.get_updates(
  File "/home/VMmanager/.local/lib/python3.8/site-packages/telegram/ext/_extbot.py", line 524, in get_updates
    updates = await super().get_updates(
  File "/home/VMmanager/.local/lib/python3.8/site-packages/telegram/_bot.py", line 331, in decorator
    result = await func(*args, **kwargs)  # skipcq: PYL-E1102
  File "/home/VMmanager/.local/lib/python3.8/site-packages/telegram/_bot.py", line 3510, in get_updates
    await self._post(
  File "/home/VMmanager/.local/lib/python3.8/site-packages/telegram/_bot.py", line 419, in _post
    return await self._do_post(
  File "/home/VMmanager/.local/lib/python3.8/site-packages/telegram/ext/_extbot.py", line 306, in _do_post
    return await super()._do_post(
  File "/home/VMmanager/.local/lib/python3.8/site-packages/telegram/_bot.py", line 450, in _do_post
    return await request.post(
  File "/home/VMmanager/.local/lib/python3.8/site-packages/telegram/request/_baserequest.py", line 165, in post
    result = await self._request_wrapper(
  File "/home/VMmanager/.local/lib/python3.8/site-packages/telegram/request/_baserequest.py", line 330, in _request_wrapper
    raise Conflict(message)
telegram.error.Conflict: Conflict: terminated by other getUpdates request; make sure that only one bot instance is running
2023-03-25 12:52:11,521 - telegram.ext._updater - ERROR - Error while getting Updates: Conflict: terminated by other getUpdates request; make sure that only one bot instance is running
2023-03-25 12:52:11,521 - telegram.ext._application - ERROR - No error handlers are registered, logging exception.
Traceback (most recent call last):
  File "/home/VMmanager/.local/lib/python3.8/site-packages/telegram/ext/_updater.py", line 607, in _network_loop_retry
    if not await action_cb():
  File "/home/VMmanager/.local/lib/python3.8/site-packages/telegram/ext/_updater.py", line 335, in polling_action_cb
    raise exc
  File "/home/VMmanager/.local/lib/python3.8/site-packages/telegram/ext/_updater.py", line 320, in polling_action_cb
    updates = await self.bot.get_updates(
  File "/home/VMmanager/.local/lib/python3.8/site-packages/telegram/ext/_extbot.py", line 524, in get_updates
    updates = await super().get_updates(
  File "/home/VMmanager/.local/lib/python3.8/site-packages/telegram/_bot.py", line 331, in decorator
    result = await func(*args, **kwargs)  # skipcq: PYL-E1102
  File "/home/VMmanager/.local/lib/python3.8/site-packages/telegram/_bot.py", line 3510, in get_updates
    await self._post(
  File "/home/VMmanager/.local/lib/python3.8/site-packages/telegram/_bot.py", line 419, in _post
    return await self._do_post(
  File "/home/VMmanager/.local/lib/python3.8/site-packages/telegram/ext/_extbot.py", line 306, in _do_post
    return await super()._do_post(
  File "/home/VMmanager/.local/lib/python3.8/site-packages/telegram/_bot.py", line 450, in _do_post
    return await request.post(
  File "/home/VMmanager/.local/lib/python3.8/site-packages/telegram/request/_baserequest.py", line 165, in post
    result = await self._request_wrapper(
  File "/home/VMmanager/.local/lib/python3.8/site-packages/telegram/request/_baserequest.py", line 330, in _request_wrapper
    raise Conflict(message)
telegram.error.Conflict: Conflict: terminated by other getUpdates request; make sure that only one bot instance is running
2023-03-25 12:52:18,362 - telegram.ext._updater - ERROR - Error while getting Updates: Conflict: terminated by other getUpdates request; make sure that only one bot instance is running
2023-03-25 12:52:18,362 - telegram.ext._application - ERROR - No error handlers are registered, logging exception.
Traceback (most recent call last):
  File "/home/VMmanager/.local/lib/python3.8/site-packages/telegram/ext/_updater.py", line 607, in _network_loop_retry
    if not await action_cb():
  File "/home/VMmanager/.local/lib/python3.8/site-packages/telegram/ext/_updater.py", line 335, in polling_action_cb
    raise exc
  File "/home/VMmanager/.local/lib/python3.8/site-packages/telegram/ext/_updater.py", line 320, in polling_action_cb
    updates = await self.bot.get_updates(
  File "/home/VMmanager/.local/lib/python3.8/site-packages/telegram/ext/_extbot.py", line 524, in get_updates
    updates = await super().get_updates(
  File "/home/VMmanager/.local/lib/python3.8/site-packages/telegram/_bot.py", line 331, in decorator
    result = await func(*args, **kwargs)  # skipcq: PYL-E1102
  File "/home/VMmanager/.local/lib/python3.8/site-packages/telegram/_bot.py", line 3510, in get_updates
    await self._post(
  File "/home/VMmanager/.local/lib/python3.8/site-packages/telegram/_bot.py", line 419, in _post
    return await self._do_post(
  File "/home/VMmanager/.local/lib/python3.8/site-packages/telegram/ext/_extbot.py", line 306, in _do_post
    return await super()._do_post(
  File "/home/VMmanager/.local/lib/python3.8/site-packages/telegram/_bot.py", line 450, in _do_post
    return await request.post(
  File "/home/VMmanager/.local/lib/python3.8/site-packages/telegram/request/_baserequest.py", line 165, in post
    result = await self._request_wrapper(
  File "/home/VMmanager/.local/lib/python3.8/site-packages/telegram/request/_baserequest.py", line 330, in _request_wrapper
    raise Conflict(message)
telegram.error.Conflict: Conflict: terminated by other getUpdates request; make sure that only one bot instance is running
2023-03-25 12:52:19,908 - telegram.ext._application - INFO - Application is stopping. This might take a moment.
2023-03-25 12:52:19,908 - telegram.ext._application - INFO - Application.stop() complete
2023-03-25 12:52:50,098 - telegram.ext._application - INFO - Application started
2023-03-25 12:54:32,296 - telegram.ext._application - INFO - Application is stopping. This might take a moment.
2023-03-25 12:54:32,297 - telegram.ext._application - INFO - Application.stop() complete
2023-03-25 12:54:39,347 - telegram.ext._application - INFO - Application started
2023-03-25 12:56:45,963 - telegram.ext._application - INFO - Application started
VBoxManage: error: Could not find a registered machine named 'Win10_03'
VBoxManage: error: Details: code VBOX_E_OBJECT_NOT_FOUND (0x80bb0001), component VirtualBoxWrap, interface IVirtualBox, callee nsISupports
VBoxManage: error: Context: "FindMachine(Bstr(VMNameOrUuid).raw(), machine.asOutParam())" at line 3138 of file VBoxManageInfo.cpp
VBoxManage: error: Could not find a registered machine named 'Win10_03'
VBoxManage: error: Details: code VBOX_E_OBJECT_NOT_FOUND (0x80bb0001), component VirtualBoxWrap, interface IVirtualBox, callee nsISupports
VBoxManage: error: Context: "FindMachine(Bstr(VMNameOrUuid).raw(), machine.asOutParam())" at line 3138 of file VBoxManageInfo.cpp
2023-03-25 14:16:15,822 - telegram.ext._application - ERROR - No error handlers are registered, logging exception.
Traceback (most recent call last):
  File "/home/VMmanager/.local/lib/python3.8/site-packages/telegram/ext/_application.py", line 1104, in process_update
    await coroutine
  File "/home/VMmanager/.local/lib/python3.8/site-packages/telegram/ext/_handler.py", line 141, in handle_update
    return await self.callback(update, context)
  File "/home/VMmanager/desarrollo/python/TelegramBot/VMbot.py", line 139, in ordenes
    await update.message.reply_text(estado(parametros))
  File "/home/VMmanager/desarrollo/python/TelegramBot/VMbot.py", line 165, in estado
    return ("Error en la llamada:" + p.stderr.decode('utf-8'))
AttributeError: 'NoneType' object has no attribute 'decode'
2023-03-25 15:43:36,622 - telegram.ext._updater - ERROR - Error while getting Updates: httpx.LocalProtocolError: Invalid input ConnectionInputs.RECV_WINDOW_UPDATE in state ConnectionState.CLOSED
2023-03-25 15:43:36,622 - telegram.ext._application - ERROR - No error handlers are registered, logging exception.
Traceback (most recent call last):
  File "/home/VMmanager/.local/lib/python3.8/site-packages/h2/connection.py", line 224, in process_input
    func, target_state = self._transitions[(self.state, input_)]
KeyError: (<ConnectionState.CLOSED: 3>, <ConnectionInputs.RECV_WINDOW_UPDATE: 13>)

During handling of the above exception, another exception occurred:

Traceback (most recent call last):
  File "/home/VMmanager/.local/lib/python3.8/site-packages/httpcore/_async/http2.py", line 112, in handle_async_request
    status, headers = await self._receive_response(
  File "/home/VMmanager/.local/lib/python3.8/site-packages/httpcore/_async/http2.py", line 229, in _receive_response
    event = await self._receive_stream_event(request, stream_id)
  File "/home/VMmanager/.local/lib/python3.8/site-packages/httpcore/_async/http2.py", line 260, in _receive_stream_event
    await self._receive_events(request, stream_id)
  File "/home/VMmanager/.local/lib/python3.8/site-packages/httpcore/_async/http2.py", line 281, in _receive_events
    events = await self._read_incoming_data(request)
  File "/home/VMmanager/.local/lib/python3.8/site-packages/httpcore/_async/http2.py", line 343, in _read_incoming_data
    events: typing.List[h2.events.Event] = self._h2_state.receive_data(data)
  File "/home/VMmanager/.local/lib/python3.8/site-packages/h2/connection.py", line 1463, in receive_data
    events.extend(self._receive_frame(frame))
  File "/home/VMmanager/.local/lib/python3.8/site-packages/h2/connection.py", line 1487, in _receive_frame
    frames, events = self._frame_dispatch_table[frame.__class__](frame)
  File "/home/VMmanager/.local/lib/python3.8/site-packages/h2/connection.py", line 1728, in _receive_window_update_frame
    events = self.state_machine.process_input(
  File "/home/VMmanager/.local/lib/python3.8/site-packages/h2/connection.py", line 228, in process_input
    raise ProtocolError(
h2.exceptions.ProtocolError: Invalid input ConnectionInputs.RECV_WINDOW_UPDATE in state ConnectionState.CLOSED

During handling of the above exception, another exception occurred:

Traceback (most recent call last):
  File "/home/VMmanager/.local/lib/python3.8/site-packages/httpx/_transports/default.py", line 60, in map_httpcore_exceptions
    yield
  File "/home/VMmanager/.local/lib/python3.8/site-packages/httpx/_transports/default.py", line 353, in handle_async_request
    resp = await self._pool.handle_async_request(req)
  File "/home/VMmanager/.local/lib/python3.8/site-packages/httpcore/_async/connection_pool.py", line 253, in handle_async_request
    raise exc
  File "/home/VMmanager/.local/lib/python3.8/site-packages/httpcore/_async/connection_pool.py", line 237, in handle_async_request
    response = await connection.handle_async_request(request)
  File "/home/VMmanager/.local/lib/python3.8/site-packages/httpcore/_async/connection.py", line 90, in handle_async_request
    return await self._connection.handle_async_request(request)
  File "/home/VMmanager/.local/lib/python3.8/site-packages/httpcore/_async/http2.py", line 142, in handle_async_request
    raise LocalProtocolError(exc)  # pragma: nocover
httpcore.LocalProtocolError: Invalid input ConnectionInputs.RECV_WINDOW_UPDATE in state ConnectionState.CLOSED

The above exception was the direct cause of the following exception:

Traceback (most recent call last):
  File "/home/VMmanager/.local/lib/python3.8/site-packages/telegram/request/_httpxrequest.py", line 199, in do_request
    res = await self._client.request(
  File "/home/VMmanager/.local/lib/python3.8/site-packages/httpx/_client.py", line 1533, in request
    return await self.send(request, auth=auth, follow_redirects=follow_redirects)
  File "/home/VMmanager/.local/lib/python3.8/site-packages/httpx/_client.py", line 1620, in send
    response = await self._send_handling_auth(
  File "/home/VMmanager/.local/lib/python3.8/site-packages/httpx/_client.py", line 1648, in _send_handling_auth
    response = await self._send_handling_redirects(
  File "/home/VMmanager/.local/lib/python3.8/site-packages/httpx/_client.py", line 1685, in _send_handling_redirects
    response = await self._send_single_request(request)
  File "/home/VMmanager/.local/lib/python3.8/site-packages/httpx/_client.py", line 1722, in _send_single_request
    response = await transport.handle_async_request(request)
  File "/home/VMmanager/.local/lib/python3.8/site-packages/httpx/_transports/default.py", line 353, in handle_async_request
    resp = await self._pool.handle_async_request(req)
  File "/usr/lib/python3.8/contextlib.py", line 131, in __exit__
    self.gen.throw(type, value, traceback)
  File "/home/VMmanager/.local/lib/python3.8/site-packages/httpx/_transports/default.py", line 77, in map_httpcore_exceptions
    raise mapped_exc(message) from exc
httpx.LocalProtocolError: Invalid input ConnectionInputs.RECV_WINDOW_UPDATE in state ConnectionState.CLOSED

The above exception was the direct cause of the following exception:

Traceback (most recent call last):
  File "/home/VMmanager/.local/lib/python3.8/site-packages/telegram/ext/_updater.py", line 607, in _network_loop_retry
    if not await action_cb():
  File "/home/VMmanager/.local/lib/python3.8/site-packages/telegram/ext/_updater.py", line 335, in polling_action_cb
    raise exc
  File "/home/VMmanager/.local/lib/python3.8/site-packages/telegram/ext/_updater.py", line 320, in polling_action_cb
    updates = await self.bot.get_updates(
  File "/home/VMmanager/.local/lib/python3.8/site-packages/telegram/ext/_extbot.py", line 524, in get_updates
    updates = await super().get_updates(
  File "/home/VMmanager/.local/lib/python3.8/site-packages/telegram/_bot.py", line 331, in decorator
    result = await func(*args, **kwargs)  # skipcq: PYL-E1102
  File "/home/VMmanager/.local/lib/python3.8/site-packages/telegram/_bot.py", line 3510, in get_updates
    await self._post(
  File "/home/VMmanager/.local/lib/python3.8/site-packages/telegram/_bot.py", line 419, in _post
    return await self._do_post(
  File "/home/VMmanager/.local/lib/python3.8/site-packages/telegram/ext/_extbot.py", line 306, in _do_post
    return await super()._do_post(
  File "/home/VMmanager/.local/lib/python3.8/site-packages/telegram/_bot.py", line 450, in _do_post
    return await request.post(
  File "/home/VMmanager/.local/lib/python3.8/site-packages/telegram/request/_baserequest.py", line 165, in post
    result = await self._request_wrapper(
  File "/home/VMmanager/.local/lib/python3.8/site-packages/telegram/request/_baserequest.py", line 288, in _request_wrapper
    raise exc
  File "/home/VMmanager/.local/lib/python3.8/site-packages/telegram/request/_baserequest.py", line 274, in _request_wrapper
    code, payload = await self.do_request(
  File "/home/VMmanager/.local/lib/python3.8/site-packages/telegram/request/_httpxrequest.py", line 223, in do_request
    raise NetworkError(f"httpx.{err.__class__.__name__}: {err}") from err
telegram.error.NetworkError: httpx.LocalProtocolError: Invalid input ConnectionInputs.RECV_WINDOW_UPDATE in state ConnectionState.CLOSED
2023-03-25 15:43:37,627 - telegram.ext._updater - ERROR - Error while getting Updates: httpx.LocalProtocolError: Invalid input ConnectionInputs.SEND_HEADERS in state ConnectionState.CLOSED
2023-03-25 15:43:37,627 - telegram.ext._application - ERROR - No error handlers are registered, logging exception.
Traceback (most recent call last):
  File "/home/VMmanager/.local/lib/python3.8/site-packages/h2/connection.py", line 224, in process_input
    func, target_state = self._transitions[(self.state, input_)]
KeyError: (<ConnectionState.CLOSED: 3>, <ConnectionInputs.SEND_HEADERS: 0>)

During handling of the above exception, another exception occurred:

Traceback (most recent call last):
  File "/home/VMmanager/.local/lib/python3.8/site-packages/httpcore/_async/http2.py", line 106, in handle_async_request
    await self._send_request_headers(request=request, stream_id=stream_id)
  File "/home/VMmanager/.local/lib/python3.8/site-packages/httpcore/_async/http2.py", line 203, in _send_request_headers
    self._h2_state.send_headers(stream_id, headers, end_stream=end_stream)
  File "/home/VMmanager/.local/lib/python3.8/site-packages/h2/connection.py", line 766, in send_headers
    self.state_machine.process_input(ConnectionInputs.SEND_HEADERS)
  File "/home/VMmanager/.local/lib/python3.8/site-packages/h2/connection.py", line 228, in process_input
    raise ProtocolError(
h2.exceptions.ProtocolError: Invalid input ConnectionInputs.SEND_HEADERS in state ConnectionState.CLOSED

During handling of the above exception, another exception occurred:

Traceback (most recent call last):
  File "/home/VMmanager/.local/lib/python3.8/site-packages/httpx/_transports/default.py", line 60, in map_httpcore_exceptions
    yield
  File "/home/VMmanager/.local/lib/python3.8/site-packages/httpx/_transports/default.py", line 353, in handle_async_request
    resp = await self._pool.handle_async_request(req)
  File "/home/VMmanager/.local/lib/python3.8/site-packages/httpcore/_async/connection_pool.py", line 253, in handle_async_request
    raise exc
  File "/home/VMmanager/.local/lib/python3.8/site-packages/httpcore/_async/connection_pool.py", line 237, in handle_async_request
    response = await connection.handle_async_request(request)
  File "/home/VMmanager/.local/lib/python3.8/site-packages/httpcore/_async/connection.py", line 90, in handle_async_request
    return await self._connection.handle_async_request(request)
  File "/home/VMmanager/.local/lib/python3.8/site-packages/httpcore/_async/http2.py", line 142, in handle_async_request
    raise LocalProtocolError(exc)  # pragma: nocover
httpcore.LocalProtocolError: Invalid input ConnectionInputs.SEND_HEADERS in state ConnectionState.CLOSED

The above exception was the direct cause of the following exception:

Traceback (most recent call last):
  File "/home/VMmanager/.local/lib/python3.8/site-packages/telegram/request/_httpxrequest.py", line 199, in do_request
    res = await self._client.request(
  File "/home/VMmanager/.local/lib/python3.8/site-packages/httpx/_client.py", line 1533, in request
    return await self.send(request, auth=auth, follow_redirects=follow_redirects)
  File "/home/VMmanager/.local/lib/python3.8/site-packages/httpx/_client.py", line 1620, in send
    response = await self._send_handling_auth(
  File "/home/VMmanager/.local/lib/python3.8/site-packages/httpx/_client.py", line 1648, in _send_handling_auth
    response = await self._send_handling_redirects(
  File "/home/VMmanager/.local/lib/python3.8/site-packages/httpx/_client.py", line 1685, in _send_handling_redirects
    response = await self._send_single_request(request)
  File "/home/VMmanager/.local/lib/python3.8/site-packages/httpx/_client.py", line 1722, in _send_single_request
    response = await transport.handle_async_request(request)
  File "/home/VMmanager/.local/lib/python3.8/site-packages/httpx/_transports/default.py", line 353, in handle_async_request
    resp = await self._pool.handle_async_request(req)
  File "/usr/lib/python3.8/contextlib.py", line 131, in __exit__
    self.gen.throw(type, value, traceback)
  File "/home/VMmanager/.local/lib/python3.8/site-packages/httpx/_transports/default.py", line 77, in map_httpcore_exceptions
    raise mapped_exc(message) from exc
httpx.LocalProtocolError: Invalid input ConnectionInputs.SEND_HEADERS in state ConnectionState.CLOSED

The above exception was the direct cause of the following exception:

Traceback (most recent call last):
  File "/home/VMmanager/.local/lib/python3.8/site-packages/telegram/ext/_updater.py", line 607, in _network_loop_retry
    if not await action_cb():
  File "/home/VMmanager/.local/lib/python3.8/site-packages/telegram/ext/_updater.py", line 335, in polling_action_cb
    raise exc
  File "/home/VMmanager/.local/lib/python3.8/site-packages/telegram/ext/_updater.py", line 320, in polling_action_cb
    updates = await self.bot.get_updates(
  File "/home/VMmanager/.local/lib/python3.8/site-packages/telegram/ext/_extbot.py", line 524, in get_updates
    updates = await super().get_updates(
  File "/home/VMmanager/.local/lib/python3.8/site-packages/telegram/_bot.py", line 331, in decorator
    result = await func(*args, **kwargs)  # skipcq: PYL-E1102
  File "/home/VMmanager/.local/lib/python3.8/site-packages/telegram/_bot.py", line 3510, in get_updates
    await self._post(
  File "/home/VMmanager/.local/lib/python3.8/site-packages/telegram/_bot.py", line 419, in _post
    return await self._do_post(
  File "/home/VMmanager/.local/lib/python3.8/site-packages/telegram/ext/_extbot.py", line 306, in _do_post
    return await super()._do_post(
  File "/home/VMmanager/.local/lib/python3.8/site-packages/telegram/_bot.py", line 450, in _do_post
    return await request.post(
  File "/home/VMmanager/.local/lib/python3.8/site-packages/telegram/request/_baserequest.py", line 165, in post
    result = await self._request_wrapper(
  File "/home/VMmanager/.local/lib/python3.8/site-packages/telegram/request/_baserequest.py", line 288, in _request_wrapper
    raise exc
  File "/home/VMmanager/.local/lib/python3.8/site-packages/telegram/request/_baserequest.py", line 274, in _request_wrapper
    code, payload = await self.do_request(
  File "/home/VMmanager/.local/lib/python3.8/site-packages/telegram/request/_httpxrequest.py", line 223, in do_request
    raise NetworkError(f"httpx.{err.__class__.__name__}: {err}") from err
telegram.error.NetworkError: httpx.LocalProtocolError: Invalid input ConnectionInputs.SEND_HEADERS in state ConnectionState.CLOSED
2023-03-25 15:43:39,132 - telegram.ext._updater - ERROR - Error while getting Updates: httpx.LocalProtocolError: Invalid input ConnectionInputs.SEND_HEADERS in state ConnectionState.CLOSED
2023-03-25 15:43:39,132 - telegram.ext._application - ERROR - No error handlers are registered, logging exception.
Traceback (most recent call last):
  File "/home/VMmanager/.local/lib/python3.8/site-packages/h2/connection.py", line 224, in process_input
    func, target_state = self._transitions[(self.state, input_)]
KeyError: (<ConnectionState.CLOSED: 3>, <ConnectionInputs.SEND_HEADERS: 0>)

During handling of the above exception, another exception occurred:

Traceback (most recent call last):
  File "/home/VMmanager/.local/lib/python3.8/site-packages/httpcore/_async/http2.py", line 106, in handle_async_request
    await self._send_request_headers(request=request, stream_id=stream_id)
  File "/home/VMmanager/.local/lib/python3.8/site-packages/httpcore/_async/http2.py", line 203, in _send_request_headers
    self._h2_state.send_headers(stream_id, headers, end_stream=end_stream)
  File "/home/VMmanager/.local/lib/python3.8/site-packages/h2/connection.py", line 766, in send_headers
    self.state_machine.process_input(ConnectionInputs.SEND_HEADERS)
  File "/home/VMmanager/.local/lib/python3.8/site-packages/h2/connection.py", line 228, in process_input
    raise ProtocolError(
h2.exceptions.ProtocolError: Invalid input ConnectionInputs.SEND_HEADERS in state ConnectionState.CLOSED

During handling of the above exception, another exception occurred:

Traceback (most recent call last):
  File "/home/VMmanager/.local/lib/python3.8/site-packages/httpx/_transports/default.py", line 60, in map_httpcore_exceptions
    yield
  File "/home/VMmanager/.local/lib/python3.8/site-packages/httpx/_transports/default.py", line 353, in handle_async_request
    resp = await self._pool.handle_async_request(req)
  File "/home/VMmanager/.local/lib/python3.8/site-packages/httpcore/_async/connection_pool.py", line 253, in handle_async_request
    raise exc
  File "/home/VMmanager/.local/lib/python3.8/site-packages/httpcore/_async/connection_pool.py", line 237, in handle_async_request
    response = await connection.handle_async_request(request)
  File "/home/VMmanager/.local/lib/python3.8/site-packages/httpcore/_async/connection.py", line 90, in handle_async_request
    return await self._connection.handle_async_request(request)
  File "/home/VMmanager/.local/lib/python3.8/site-packages/httpcore/_async/http2.py", line 142, in handle_async_request
    raise LocalProtocolError(exc)  # pragma: nocover
httpcore.LocalProtocolError: Invalid input ConnectionInputs.SEND_HEADERS in state ConnectionState.CLOSED

The above exception was the direct cause of the following exception:

Traceback (most recent call last):
  File "/home/VMmanager/.local/lib/python3.8/site-packages/telegram/request/_httpxrequest.py", line 199, in do_request
    res = await self._client.request(
  File "/home/VMmanager/.local/lib/python3.8/site-packages/httpx/_client.py", line 1533, in request
    return await self.send(request, auth=auth, follow_redirects=follow_redirects)
  File "/home/VMmanager/.local/lib/python3.8/site-packages/httpx/_client.py", line 1620, in send
    response = await self._send_handling_auth(
  File "/home/VMmanager/.local/lib/python3.8/site-packages/httpx/_client.py", line 1648, in _send_handling_auth
    response = await self._send_handling_redirects(
  File "/home/VMmanager/.local/lib/python3.8/site-packages/httpx/_client.py", line 1685, in _send_handling_redirects
    response = await self._send_single_request(request)
  File "/home/VMmanager/.local/lib/python3.8/site-packages/httpx/_client.py", line 1722, in _send_single_request
    response = await transport.handle_async_request(request)
  File "/home/VMmanager/.local/lib/python3.8/site-packages/httpx/_transports/default.py", line 353, in handle_async_request
    resp = await self._pool.handle_async_request(req)
  File "/usr/lib/python3.8/contextlib.py", line 131, in __exit__
    self.gen.throw(type, value, traceback)
  File "/home/VMmanager/.local/lib/python3.8/site-packages/httpx/_transports/default.py", line 77, in map_httpcore_exceptions
    raise mapped_exc(message) from exc
httpx.LocalProtocolError: Invalid input ConnectionInputs.SEND_HEADERS in state ConnectionState.CLOSED

The above exception was the direct cause of the following exception:

Traceback (most recent call last):
  File "/home/VMmanager/.local/lib/python3.8/site-packages/telegram/ext/_updater.py", line 607, in _network_loop_retry
    if not await action_cb():
  File "/home/VMmanager/.local/lib/python3.8/site-packages/telegram/ext/_updater.py", line 335, in polling_action_cb
    raise exc
  File "/home/VMmanager/.local/lib/python3.8/site-packages/telegram/ext/_updater.py", line 320, in polling_action_cb
    updates = await self.bot.get_updates(
  File "/home/VMmanager/.local/lib/python3.8/site-packages/telegram/ext/_extbot.py", line 524, in get_updates
    updates = await super().get_updates(
  File "/home/VMmanager/.local/lib/python3.8/site-packages/telegram/_bot.py", line 331, in decorator
    result = await func(*args, **kwargs)  # skipcq: PYL-E1102
  File "/home/VMmanager/.local/lib/python3.8/site-packages/telegram/_bot.py", line 3510, in get_updates
    await self._post(
  File "/home/VMmanager/.local/lib/python3.8/site-packages/telegram/_bot.py", line 419, in _post
    return await self._do_post(
  File "/home/VMmanager/.local/lib/python3.8/site-packages/telegram/ext/_extbot.py", line 306, in _do_post
    return await super()._do_post(
  File "/home/VMmanager/.local/lib/python3.8/site-packages/telegram/_bot.py", line 450, in _do_post
    return await request.post(
  File "/home/VMmanager/.local/lib/python3.8/site-packages/telegram/request/_baserequest.py", line 165, in post
    result = await self._request_wrapper(
  File "/home/VMmanager/.local/lib/python3.8/site-packages/telegram/request/_baserequest.py", line 288, in _request_wrapper
    raise exc
  File "/home/VMmanager/.local/lib/python3.8/site-packages/telegram/request/_baserequest.py", line 274, in _request_wrapper
    code, payload = await self.do_request(
  File "/home/VMmanager/.local/lib/python3.8/site-packages/telegram/request/_httpxrequest.py", line 223, in do_request
    raise NetworkError(f"httpx.{err.__class__.__name__}: {err}") from err
telegram.error.NetworkError: httpx.LocalProtocolError: Invalid input ConnectionInputs.SEND_HEADERS in state ConnectionState.CLOSED
2023-03-25 15:43:41,388 - telegram.ext._updater - ERROR - Error while getting Updates: httpx.LocalProtocolError: Invalid input ConnectionInputs.SEND_HEADERS in state ConnectionState.CLOSED
2023-03-25 15:43:41,388 - telegram.ext._application - ERROR - No error handlers are registered, logging exception.
Traceback (most recent call last):
  File "/home/VMmanager/.local/lib/python3.8/site-packages/h2/connection.py", line 224, in process_input
    func, target_state = self._transitions[(self.state, input_)]
KeyError: (<ConnectionState.CLOSED: 3>, <ConnectionInputs.SEND_HEADERS: 0>)

During handling of the above exception, another exception occurred:

Traceback (most recent call last):
  File "/home/VMmanager/.local/lib/python3.8/site-packages/httpcore/_async/http2.py", line 106, in handle_async_request
    await self._send_request_headers(request=request, stream_id=stream_id)
  File "/home/VMmanager/.local/lib/python3.8/site-packages/httpcore/_async/http2.py", line 203, in _send_request_headers
    self._h2_state.send_headers(stream_id, headers, end_stream=end_stream)
  File "/home/VMmanager/.local/lib/python3.8/site-packages/h2/connection.py", line 766, in send_headers
    self.state_machine.process_input(ConnectionInputs.SEND_HEADERS)
  File "/home/VMmanager/.local/lib/python3.8/site-packages/h2/connection.py", line 228, in process_input
    raise ProtocolError(
h2.exceptions.ProtocolError: Invalid input ConnectionInputs.SEND_HEADERS in state ConnectionState.CLOSED

During handling of the above exception, another exception occurred:

Traceback (most recent call last):
  File "/home/VMmanager/.local/lib/python3.8/site-packages/httpx/_transports/default.py", line 60, in map_httpcore_exceptions
    yield
  File "/home/VMmanager/.local/lib/python3.8/site-packages/httpx/_transports/default.py", line 353, in handle_async_request
    resp = await self._pool.handle_async_request(req)
  File "/home/VMmanager/.local/lib/python3.8/site-packages/httpcore/_async/connection_pool.py", line 253, in handle_async_request
    raise exc
  File "/home/VMmanager/.local/lib/python3.8/site-packages/httpcore/_async/connection_pool.py", line 237, in handle_async_request
    response = await connection.handle_async_request(request)
  File "/home/VMmanager/.local/lib/python3.8/site-packages/httpcore/_async/connection.py", line 90, in handle_async_request
    return await self._connection.handle_async_request(request)
  File "/home/VMmanager/.local/lib/python3.8/site-packages/httpcore/_async/http2.py", line 142, in handle_async_request
    raise LocalProtocolError(exc)  # pragma: nocover
httpcore.LocalProtocolError: Invalid input ConnectionInputs.SEND_HEADERS in state ConnectionState.CLOSED

The above exception was the direct cause of the following exception:

Traceback (most recent call last):
  File "/home/VMmanager/.local/lib/python3.8/site-packages/telegram/request/_httpxrequest.py", line 199, in do_request
    res = await self._client.request(
  File "/home/VMmanager/.local/lib/python3.8/site-packages/httpx/_client.py", line 1533, in request
    return await self.send(request, auth=auth, follow_redirects=follow_redirects)
  File "/home/VMmanager/.local/lib/python3.8/site-packages/httpx/_client.py", line 1620, in send
    response = await self._send_handling_auth(
  File "/home/VMmanager/.local/lib/python3.8/site-packages/httpx/_client.py", line 1648, in _send_handling_auth
    response = await self._send_handling_redirects(
  File "/home/VMmanager/.local/lib/python3.8/site-packages/httpx/_client.py", line 1685, in _send_handling_redirects
    response = await self._send_single_request(request)
  File "/home/VMmanager/.local/lib/python3.8/site-packages/httpx/_client.py", line 1722, in _send_single_request
    response = await transport.handle_async_request(request)
  File "/home/VMmanager/.local/lib/python3.8/site-packages/httpx/_transports/default.py", line 353, in handle_async_request
    resp = await self._pool.handle_async_request(req)
  File "/usr/lib/python3.8/contextlib.py", line 131, in __exit__
    self.gen.throw(type, value, traceback)
  File "/home/VMmanager/.local/lib/python3.8/site-packages/httpx/_transports/default.py", line 77, in map_httpcore_exceptions
    raise mapped_exc(message) from exc
httpx.LocalProtocolError: Invalid input ConnectionInputs.SEND_HEADERS in state ConnectionState.CLOSED

The above exception was the direct cause of the following exception:

Traceback (most recent call last):
  File "/home/VMmanager/.local/lib/python3.8/site-packages/telegram/ext/_updater.py", line 607, in _network_loop_retry
    if not await action_cb():
  File "/home/VMmanager/.local/lib/python3.8/site-packages/telegram/ext/_updater.py", line 335, in polling_action_cb
    raise exc
  File "/home/VMmanager/.local/lib/python3.8/site-packages/telegram/ext/_updater.py", line 320, in polling_action_cb
    updates = await self.bot.get_updates(
  File "/home/VMmanager/.local/lib/python3.8/site-packages/telegram/ext/_extbot.py", line 524, in get_updates
    updates = await super().get_updates(
  File "/home/VMmanager/.local/lib/python3.8/site-packages/telegram/_bot.py", line 331, in decorator
    result = await func(*args, **kwargs)  # skipcq: PYL-E1102
  File "/home/VMmanager/.local/lib/python3.8/site-packages/telegram/_bot.py", line 3510, in get_updates
    await self._post(
  File "/home/VMmanager/.local/lib/python3.8/site-packages/telegram/_bot.py", line 419, in _post
    return await self._do_post(
  File "/home/VMmanager/.local/lib/python3.8/site-packages/telegram/ext/_extbot.py", line 306, in _do_post
    return await super()._do_post(
  File "/home/VMmanager/.local/lib/python3.8/site-packages/telegram/_bot.py", line 450, in _do_post
    return await request.post(
  File "/home/VMmanager/.local/lib/python3.8/site-packages/telegram/request/_baserequest.py", line 165, in post
    result = await self._request_wrapper(
  File "/home/VMmanager/.local/lib/python3.8/site-packages/telegram/request/_baserequest.py", line 288, in _request_wrapper
    raise exc
  File "/home/VMmanager/.local/lib/python3.8/site-packages/telegram/request/_baserequest.py", line 274, in _request_wrapper
    code, payload = await self.do_request(
  File "/home/VMmanager/.local/lib/python3.8/site-packages/telegram/request/_httpxrequest.py", line 223, in do_request
    raise NetworkError(f"httpx.{err.__class__.__name__}: {err}") from err
telegram.error.NetworkError: httpx.LocalProtocolError: Invalid input ConnectionInputs.SEND_HEADERS in state ConnectionState.CLOSED
2023-03-25 15:43:44,770 - telegram.ext._updater - ERROR - Error while getting Updates: httpx.LocalProtocolError: Invalid input ConnectionInputs.SEND_HEADERS in state ConnectionState.CLOSED
2023-03-25 15:43:44,770 - telegram.ext._application - ERROR - No error handlers are registered, logging exception.
Traceback (most recent call last):
  File "/home/VMmanager/.local/lib/python3.8/site-packages/h2/connection.py", line 224, in process_input
    func, target_state = self._transitions[(self.state, input_)]
KeyError: (<ConnectionState.CLOSED: 3>, <ConnectionInputs.SEND_HEADERS: 0>)

During handling of the above exception, another exception occurred:

Traceback (most recent call last):
  File "/home/VMmanager/.local/lib/python3.8/site-packages/httpcore/_async/http2.py", line 106, in handle_async_request
    await self._send_request_headers(request=request, stream_id=stream_id)
  File "/home/VMmanager/.local/lib/python3.8/site-packages/httpcore/_async/http2.py", line 203, in _send_request_headers
    self._h2_state.send_headers(stream_id, headers, end_stream=end_stream)
  File "/home/VMmanager/.local/lib/python3.8/site-packages/h2/connection.py", line 766, in send_headers
    self.state_machine.process_input(ConnectionInputs.SEND_HEADERS)
  File "/home/VMmanager/.local/lib/python3.8/site-packages/h2/connection.py", line 228, in process_input
    raise ProtocolError(
h2.exceptions.ProtocolError: Invalid input ConnectionInputs.SEND_HEADERS in state ConnectionState.CLOSED

During handling of the above exception, another exception occurred:

Traceback (most recent call last):
  File "/home/VMmanager/.local/lib/python3.8/site-packages/httpx/_transports/default.py", line 60, in map_httpcore_exceptions
    yield
  File "/home/VMmanager/.local/lib/python3.8/site-packages/httpx/_transports/default.py", line 353, in handle_async_request
    resp = await self._pool.handle_async_request(req)
  File "/home/VMmanager/.local/lib/python3.8/site-packages/httpcore/_async/connection_pool.py", line 253, in handle_async_request
    raise exc
  File "/home/VMmanager/.local/lib/python3.8/site-packages/httpcore/_async/connection_pool.py", line 237, in handle_async_request
    response = await connection.handle_async_request(request)
  File "/home/VMmanager/.local/lib/python3.8/site-packages/httpcore/_async/connection.py", line 90, in handle_async_request
    return await self._connection.handle_async_request(request)
  File "/home/VMmanager/.local/lib/python3.8/site-packages/httpcore/_async/http2.py", line 142, in handle_async_request
    raise LocalProtocolError(exc)  # pragma: nocover
httpcore.LocalProtocolError: Invalid input ConnectionInputs.SEND_HEADERS in state ConnectionState.CLOSED

The above exception was the direct cause of the following exception:

Traceback (most recent call last):
  File "/home/VMmanager/.local/lib/python3.8/site-packages/telegram/request/_httpxrequest.py", line 199, in do_request
    res = await self._client.request(
  File "/home/VMmanager/.local/lib/python3.8/site-packages/httpx/_client.py", line 1533, in request
    return await self.send(request, auth=auth, follow_redirects=follow_redirects)
  File "/home/VMmanager/.local/lib/python3.8/site-packages/httpx/_client.py", line 1620, in send
    response = await self._send_handling_auth(
  File "/home/VMmanager/.local/lib/python3.8/site-packages/httpx/_client.py", line 1648, in _send_handling_auth
    response = await self._send_handling_redirects(
  File "/home/VMmanager/.local/lib/python3.8/site-packages/httpx/_client.py", line 1685, in _send_handling_redirects
    response = await self._send_single_request(request)
  File "/home/VMmanager/.local/lib/python3.8/site-packages/httpx/_client.py", line 1722, in _send_single_request
    response = await transport.handle_async_request(request)
  File "/home/VMmanager/.local/lib/python3.8/site-packages/httpx/_transports/default.py", line 353, in handle_async_request
    resp = await self._pool.handle_async_request(req)
  File "/usr/lib/python3.8/contextlib.py", line 131, in __exit__
    self.gen.throw(type, value, traceback)
  File "/home/VMmanager/.local/lib/python3.8/site-packages/httpx/_transports/default.py", line 77, in map_httpcore_exceptions
    raise mapped_exc(message) from exc
httpx.LocalProtocolError: Invalid input ConnectionInputs.SEND_HEADERS in state ConnectionState.CLOSED

The above exception was the direct cause of the following exception:

Traceback (most recent call last):
  File "/home/VMmanager/.local/lib/python3.8/site-packages/telegram/ext/_updater.py", line 607, in _network_loop_retry
    if not await action_cb():
  File "/home/VMmanager/.local/lib/python3.8/site-packages/telegram/ext/_updater.py", line 335, in polling_action_cb
    raise exc
  File "/home/VMmanager/.local/lib/python3.8/site-packages/telegram/ext/_updater.py", line 320, in polling_action_cb
    updates = await self.bot.get_updates(
  File "/home/VMmanager/.local/lib/python3.8/site-packages/telegram/ext/_extbot.py", line 524, in get_updates
    updates = await super().get_updates(
  File "/home/VMmanager/.local/lib/python3.8/site-packages/telegram/_bot.py", line 331, in decorator
    result = await func(*args, **kwargs)  # skipcq: PYL-E1102
  File "/home/VMmanager/.local/lib/python3.8/site-packages/telegram/_bot.py", line 3510, in get_updates
    await self._post(
  File "/home/VMmanager/.local/lib/python3.8/site-packages/telegram/_bot.py", line 419, in _post
    return await self._do_post(
  File "/home/VMmanager/.local/lib/python3.8/site-packages/telegram/ext/_extbot.py", line 306, in _do_post
    return await super()._do_post(
  File "/home/VMmanager/.local/lib/python3.8/site-packages/telegram/_bot.py", line 450, in _do_post
    return await request.post(
  File "/home/VMmanager/.local/lib/python3.8/site-packages/telegram/request/_baserequest.py", line 165, in post
    result = await self._request_wrapper(
  File "/home/VMmanager/.local/lib/python3.8/site-packages/telegram/request/_baserequest.py", line 288, in _request_wrapper
    raise exc
  File "/home/VMmanager/.local/lib/python3.8/site-packages/telegram/request/_baserequest.py", line 274, in _request_wrapper
    code, payload = await self.do_request(
  File "/home/VMmanager/.local/lib/python3.8/site-packages/telegram/request/_httpxrequest.py", line 223, in do_request
    raise NetworkError(f"httpx.{err.__class__.__name__}: {err}") from err
telegram.error.NetworkError: httpx.LocalProtocolError: Invalid input ConnectionInputs.SEND_HEADERS in state ConnectionState.CLOSED
2023-03-25 16:32:11,276 - telegram.ext._application - INFO - Application started
2023-03-25 17:28:54,118 - telegram.ext._application - INFO - Application started
2023-03-25 20:15:43,255 - telegram.ext._updater - ERROR - Error while getting Updates: httpx.LocalProtocolError: Invalid input ConnectionInputs.RECV_WINDOW_UPDATE in state ConnectionState.CLOSED
2023-03-25 20:15:43,256 - telegram.ext._application - ERROR - No error handlers are registered, logging exception.
Traceback (most recent call last):
  File "/home/VMmanager/.local/lib/python3.8/site-packages/h2/connection.py", line 224, in process_input
    func, target_state = self._transitions[(self.state, input_)]
KeyError: (<ConnectionState.CLOSED: 3>, <ConnectionInputs.RECV_WINDOW_UPDATE: 13>)

During handling of the above exception, another exception occurred:

Traceback (most recent call last):
  File "/home/VMmanager/.local/lib/python3.8/site-packages/httpcore/_async/http2.py", line 112, in handle_async_request
    status, headers = await self._receive_response(
  File "/home/VMmanager/.local/lib/python3.8/site-packages/httpcore/_async/http2.py", line 229, in _receive_response
    event = await self._receive_stream_event(request, stream_id)
  File "/home/VMmanager/.local/lib/python3.8/site-packages/httpcore/_async/http2.py", line 260, in _receive_stream_event
    await self._receive_events(request, stream_id)
  File "/home/VMmanager/.local/lib/python3.8/site-packages/httpcore/_async/http2.py", line 281, in _receive_events
    events = await self._read_incoming_data(request)
  File "/home/VMmanager/.local/lib/python3.8/site-packages/httpcore/_async/http2.py", line 343, in _read_incoming_data
    events: typing.List[h2.events.Event] = self._h2_state.receive_data(data)
  File "/home/VMmanager/.local/lib/python3.8/site-packages/h2/connection.py", line 1463, in receive_data
    events.extend(self._receive_frame(frame))
  File "/home/VMmanager/.local/lib/python3.8/site-packages/h2/connection.py", line 1487, in _receive_frame
    frames, events = self._frame_dispatch_table[frame.__class__](frame)
  File "/home/VMmanager/.local/lib/python3.8/site-packages/h2/connection.py", line 1728, in _receive_window_update_frame
    events = self.state_machine.process_input(
  File "/home/VMmanager/.local/lib/python3.8/site-packages/h2/connection.py", line 228, in process_input
    raise ProtocolError(
h2.exceptions.ProtocolError: Invalid input ConnectionInputs.RECV_WINDOW_UPDATE in state ConnectionState.CLOSED

During handling of the above exception, another exception occurred:

Traceback (most recent call last):
  File "/home/VMmanager/.local/lib/python3.8/site-packages/httpx/_transports/default.py", line 60, in map_httpcore_exceptions
    yield
  File "/home/VMmanager/.local/lib/python3.8/site-packages/httpx/_transports/default.py", line 353, in handle_async_request
    resp = await self._pool.handle_async_request(req)
  File "/home/VMmanager/.local/lib/python3.8/site-packages/httpcore/_async/connection_pool.py", line 253, in handle_async_request
    raise exc
  File "/home/VMmanager/.local/lib/python3.8/site-packages/httpcore/_async/connection_pool.py", line 237, in handle_async_request
    response = await connection.handle_async_request(request)
  File "/home/VMmanager/.local/lib/python3.8/site-packages/httpcore/_async/connection.py", line 90, in handle_async_request
    return await self._connection.handle_async_request(request)
  File "/home/VMmanager/.local/lib/python3.8/site-packages/httpcore/_async/http2.py", line 142, in handle_async_request
    raise LocalProtocolError(exc)  # pragma: nocover
httpcore.LocalProtocolError: Invalid input ConnectionInputs.RECV_WINDOW_UPDATE in state ConnectionState.CLOSED

The above exception was the direct cause of the following exception:

Traceback (most recent call last):
  File "/home/VMmanager/.local/lib/python3.8/site-packages/telegram/request/_httpxrequest.py", line 199, in do_request
    res = await self._client.request(
  File "/home/VMmanager/.local/lib/python3.8/site-packages/httpx/_client.py", line 1533, in request
    return await self.send(request, auth=auth, follow_redirects=follow_redirects)
  File "/home/VMmanager/.local/lib/python3.8/site-packages/httpx/_client.py", line 1620, in send
    response = await self._send_handling_auth(
  File "/home/VMmanager/.local/lib/python3.8/site-packages/httpx/_client.py", line 1648, in _send_handling_auth
    response = await self._send_handling_redirects(
  File "/home/VMmanager/.local/lib/python3.8/site-packages/httpx/_client.py", line 1685, in _send_handling_redirects
    response = await self._send_single_request(request)
  File "/home/VMmanager/.local/lib/python3.8/site-packages/httpx/_client.py", line 1722, in _send_single_request
    response = await transport.handle_async_request(request)
  File "/home/VMmanager/.local/lib/python3.8/site-packages/httpx/_transports/default.py", line 353, in handle_async_request
    resp = await self._pool.handle_async_request(req)
  File "/usr/lib/python3.8/contextlib.py", line 131, in __exit__
    self.gen.throw(type, value, traceback)
  File "/home/VMmanager/.local/lib/python3.8/site-packages/httpx/_transports/default.py", line 77, in map_httpcore_exceptions
    raise mapped_exc(message) from exc
httpx.LocalProtocolError: Invalid input ConnectionInputs.RECV_WINDOW_UPDATE in state ConnectionState.CLOSED

The above exception was the direct cause of the following exception:

Traceback (most recent call last):
  File "/home/VMmanager/.local/lib/python3.8/site-packages/telegram/ext/_updater.py", line 607, in _network_loop_retry
    if not await action_cb():
  File "/home/VMmanager/.local/lib/python3.8/site-packages/telegram/ext/_updater.py", line 335, in polling_action_cb
    raise exc
  File "/home/VMmanager/.local/lib/python3.8/site-packages/telegram/ext/_updater.py", line 320, in polling_action_cb
    updates = await self.bot.get_updates(
  File "/home/VMmanager/.local/lib/python3.8/site-packages/telegram/ext/_extbot.py", line 524, in get_updates
    updates = await super().get_updates(
  File "/home/VMmanager/.local/lib/python3.8/site-packages/telegram/_bot.py", line 331, in decorator
    result = await func(*args, **kwargs)  # skipcq: PYL-E1102
  File "/home/VMmanager/.local/lib/python3.8/site-packages/telegram/_bot.py", line 3510, in get_updates
    await self._post(
  File "/home/VMmanager/.local/lib/python3.8/site-packages/telegram/_bot.py", line 419, in _post
    return await self._do_post(
  File "/home/VMmanager/.local/lib/python3.8/site-packages/telegram/ext/_extbot.py", line 306, in _do_post
    return await super()._do_post(
  File "/home/VMmanager/.local/lib/python3.8/site-packages/telegram/_bot.py", line 450, in _do_post
    return await request.post(
  File "/home/VMmanager/.local/lib/python3.8/site-packages/telegram/request/_baserequest.py", line 165, in post
    result = await self._request_wrapper(
  File "/home/VMmanager/.local/lib/python3.8/site-packages/telegram/request/_baserequest.py", line 288, in _request_wrapper
    raise exc
  File "/home/VMmanager/.local/lib/python3.8/site-packages/telegram/request/_baserequest.py", line 274, in _request_wrapper
    code, payload = await self.do_request(
  File "/home/VMmanager/.local/lib/python3.8/site-packages/telegram/request/_httpxrequest.py", line 223, in do_request
    raise NetworkError(f"httpx.{err.__class__.__name__}: {err}") from err
telegram.error.NetworkError: httpx.LocalProtocolError: Invalid input ConnectionInputs.RECV_WINDOW_UPDATE in state ConnectionState.CLOSED
2023-03-25 20:15:44,260 - telegram.ext._updater - ERROR - Error while getting Updates: httpx.LocalProtocolError: Invalid input ConnectionInputs.SEND_HEADERS in state ConnectionState.CLOSED
2023-03-25 20:15:44,261 - telegram.ext._application - ERROR - No error handlers are registered, logging exception.
Traceback (most recent call last):
  File "/home/VMmanager/.local/lib/python3.8/site-packages/h2/connection.py", line 224, in process_input
    func, target_state = self._transitions[(self.state, input_)]
KeyError: (<ConnectionState.CLOSED: 3>, <ConnectionInputs.SEND_HEADERS: 0>)

During handling of the above exception, another exception occurred:

Traceback (most recent call last):
  File "/home/VMmanager/.local/lib/python3.8/site-packages/httpcore/_async/http2.py", line 106, in handle_async_request
    await self._send_request_headers(request=request, stream_id=stream_id)
  File "/home/VMmanager/.local/lib/python3.8/site-packages/httpcore/_async/http2.py", line 203, in _send_request_headers
    self._h2_state.send_headers(stream_id, headers, end_stream=end_stream)
  File "/home/VMmanager/.local/lib/python3.8/site-packages/h2/connection.py", line 766, in send_headers
    self.state_machine.process_input(ConnectionInputs.SEND_HEADERS)
  File "/home/VMmanager/.local/lib/python3.8/site-packages/h2/connection.py", line 228, in process_input
    raise ProtocolError(
h2.exceptions.ProtocolError: Invalid input ConnectionInputs.SEND_HEADERS in state ConnectionState.CLOSED

During handling of the above exception, another exception occurred:

Traceback (most recent call last):
  File "/home/VMmanager/.local/lib/python3.8/site-packages/httpx/_transports/default.py", line 60, in map_httpcore_exceptions
    yield
  File "/home/VMmanager/.local/lib/python3.8/site-packages/httpx/_transports/default.py", line 353, in handle_async_request
    resp = await self._pool.handle_async_request(req)
  File "/home/VMmanager/.local/lib/python3.8/site-packages/httpcore/_async/connection_pool.py", line 253, in handle_async_request
    raise exc
  File "/home/VMmanager/.local/lib/python3.8/site-packages/httpcore/_async/connection_pool.py", line 237, in handle_async_request
    response = await connection.handle_async_request(request)
  File "/home/VMmanager/.local/lib/python3.8/site-packages/httpcore/_async/connection.py", line 90, in handle_async_request
    return await self._connection.handle_async_request(request)
  File "/home/VMmanager/.local/lib/python3.8/site-packages/httpcore/_async/http2.py", line 142, in handle_async_request
    raise LocalProtocolError(exc)  # pragma: nocover
httpcore.LocalProtocolError: Invalid input ConnectionInputs.SEND_HEADERS in state ConnectionState.CLOSED

The above exception was the direct cause of the following exception:

Traceback (most recent call last):
  File "/home/VMmanager/.local/lib/python3.8/site-packages/telegram/request/_httpxrequest.py", line 199, in do_request
    res = await self._client.request(
  File "/home/VMmanager/.local/lib/python3.8/site-packages/httpx/_client.py", line 1533, in request
    return await self.send(request, auth=auth, follow_redirects=follow_redirects)
  File "/home/VMmanager/.local/lib/python3.8/site-packages/httpx/_client.py", line 1620, in send
    response = await self._send_handling_auth(
  File "/home/VMmanager/.local/lib/python3.8/site-packages/httpx/_client.py", line 1648, in _send_handling_auth
    response = await self._send_handling_redirects(
  File "/home/VMmanager/.local/lib/python3.8/site-packages/httpx/_client.py", line 1685, in _send_handling_redirects
    response = await self._send_single_request(request)
  File "/home/VMmanager/.local/lib/python3.8/site-packages/httpx/_client.py", line 1722, in _send_single_request
    response = await transport.handle_async_request(request)
  File "/home/VMmanager/.local/lib/python3.8/site-packages/httpx/_transports/default.py", line 353, in handle_async_request
    resp = await self._pool.handle_async_request(req)
  File "/usr/lib/python3.8/contextlib.py", line 131, in __exit__
    self.gen.throw(type, value, traceback)
  File "/home/VMmanager/.local/lib/python3.8/site-packages/httpx/_transports/default.py", line 77, in map_httpcore_exceptions
    raise mapped_exc(message) from exc
httpx.LocalProtocolError: Invalid input ConnectionInputs.SEND_HEADERS in state ConnectionState.CLOSED

The above exception was the direct cause of the following exception:

Traceback (most recent call last):
  File "/home/VMmanager/.local/lib/python3.8/site-packages/telegram/ext/_updater.py", line 607, in _network_loop_retry
    if not await action_cb():
  File "/home/VMmanager/.local/lib/python3.8/site-packages/telegram/ext/_updater.py", line 335, in polling_action_cb
    raise exc
  File "/home/VMmanager/.local/lib/python3.8/site-packages/telegram/ext/_updater.py", line 320, in polling_action_cb
    updates = await self.bot.get_updates(
  File "/home/VMmanager/.local/lib/python3.8/site-packages/telegram/ext/_extbot.py", line 524, in get_updates
    updates = await super().get_updates(
  File "/home/VMmanager/.local/lib/python3.8/site-packages/telegram/_bot.py", line 331, in decorator
    result = await func(*args, **kwargs)  # skipcq: PYL-E1102
  File "/home/VMmanager/.local/lib/python3.8/site-packages/telegram/_bot.py", line 3510, in get_updates
    await self._post(
  File "/home/VMmanager/.local/lib/python3.8/site-packages/telegram/_bot.py", line 419, in _post
    return await self._do_post(
  File "/home/VMmanager/.local/lib/python3.8/site-packages/telegram/ext/_extbot.py", line 306, in _do_post
    return await super()._do_post(
  File "/home/VMmanager/.local/lib/python3.8/site-packages/telegram/_bot.py", line 450, in _do_post
    return await request.post(
  File "/home/VMmanager/.local/lib/python3.8/site-packages/telegram/request/_baserequest.py", line 165, in post
    result = await self._request_wrapper(
  File "/home/VMmanager/.local/lib/python3.8/site-packages/telegram/request/_baserequest.py", line 288, in _request_wrapper
    raise exc
  File "/home/VMmanager/.local/lib/python3.8/site-packages/telegram/request/_baserequest.py", line 274, in _request_wrapper
    code, payload = await self.do_request(
  File "/home/VMmanager/.local/lib/python3.8/site-packages/telegram/request/_httpxrequest.py", line 223, in do_request
    raise NetworkError(f"httpx.{err.__class__.__name__}: {err}") from err
telegram.error.NetworkError: httpx.LocalProtocolError: Invalid input ConnectionInputs.SEND_HEADERS in state ConnectionState.CLOSED
2023-03-25 20:15:45,765 - telegram.ext._updater - ERROR - Error while getting Updates: httpx.LocalProtocolError: Invalid input ConnectionInputs.SEND_HEADERS in state ConnectionState.CLOSED
2023-03-25 20:15:45,765 - telegram.ext._application - ERROR - No error handlers are registered, logging exception.
Traceback (most recent call last):
  File "/home/VMmanager/.local/lib/python3.8/site-packages/h2/connection.py", line 224, in process_input
    func, target_state = self._transitions[(self.state, input_)]
KeyError: (<ConnectionState.CLOSED: 3>, <ConnectionInputs.SEND_HEADERS: 0>)

During handling of the above exception, another exception occurred:

Traceback (most recent call last):
  File "/home/VMmanager/.local/lib/python3.8/site-packages/httpcore/_async/http2.py", line 106, in handle_async_request
    await self._send_request_headers(request=request, stream_id=stream_id)
  File "/home/VMmanager/.local/lib/python3.8/site-packages/httpcore/_async/http2.py", line 203, in _send_request_headers
    self._h2_state.send_headers(stream_id, headers, end_stream=end_stream)
  File "/home/VMmanager/.local/lib/python3.8/site-packages/h2/connection.py", line 766, in send_headers
    self.state_machine.process_input(ConnectionInputs.SEND_HEADERS)
  File "/home/VMmanager/.local/lib/python3.8/site-packages/h2/connection.py", line 228, in process_input
    raise ProtocolError(
h2.exceptions.ProtocolError: Invalid input ConnectionInputs.SEND_HEADERS in state ConnectionState.CLOSED

During handling of the above exception, another exception occurred:

Traceback (most recent call last):
  File "/home/VMmanager/.local/lib/python3.8/site-packages/httpx/_transports/default.py", line 60, in map_httpcore_exceptions
    yield
  File "/home/VMmanager/.local/lib/python3.8/site-packages/httpx/_transports/default.py", line 353, in handle_async_request
    resp = await self._pool.handle_async_request(req)
  File "/home/VMmanager/.local/lib/python3.8/site-packages/httpcore/_async/connection_pool.py", line 253, in handle_async_request
    raise exc
  File "/home/VMmanager/.local/lib/python3.8/site-packages/httpcore/_async/connection_pool.py", line 237, in handle_async_request
    response = await connection.handle_async_request(request)
  File "/home/VMmanager/.local/lib/python3.8/site-packages/httpcore/_async/connection.py", line 90, in handle_async_request
    return await self._connection.handle_async_request(request)
  File "/home/VMmanager/.local/lib/python3.8/site-packages/httpcore/_async/http2.py", line 142, in handle_async_request
    raise LocalProtocolError(exc)  # pragma: nocover
httpcore.LocalProtocolError: Invalid input ConnectionInputs.SEND_HEADERS in state ConnectionState.CLOSED

The above exception was the direct cause of the following exception:

Traceback (most recent call last):
  File "/home/VMmanager/.local/lib/python3.8/site-packages/telegram/request/_httpxrequest.py", line 199, in do_request
    res = await self._client.request(
  File "/home/VMmanager/.local/lib/python3.8/site-packages/httpx/_client.py", line 1533, in request
    return await self.send(request, auth=auth, follow_redirects=follow_redirects)
  File "/home/VMmanager/.local/lib/python3.8/site-packages/httpx/_client.py", line 1620, in send
    response = await self._send_handling_auth(
  File "/home/VMmanager/.local/lib/python3.8/site-packages/httpx/_client.py", line 1648, in _send_handling_auth
    response = await self._send_handling_redirects(
  File "/home/VMmanager/.local/lib/python3.8/site-packages/httpx/_client.py", line 1685, in _send_handling_redirects
    response = await self._send_single_request(request)
  File "/home/VMmanager/.local/lib/python3.8/site-packages/httpx/_client.py", line 1722, in _send_single_request
    response = await transport.handle_async_request(request)
  File "/home/VMmanager/.local/lib/python3.8/site-packages/httpx/_transports/default.py", line 353, in handle_async_request
    resp = await self._pool.handle_async_request(req)
  File "/usr/lib/python3.8/contextlib.py", line 131, in __exit__
    self.gen.throw(type, value, traceback)
  File "/home/VMmanager/.local/lib/python3.8/site-packages/httpx/_transports/default.py", line 77, in map_httpcore_exceptions
    raise mapped_exc(message) from exc
httpx.LocalProtocolError: Invalid input ConnectionInputs.SEND_HEADERS in state ConnectionState.CLOSED

The above exception was the direct cause of the following exception:

Traceback (most recent call last):
  File "/home/VMmanager/.local/lib/python3.8/site-packages/telegram/ext/_updater.py", line 607, in _network_loop_retry
    if not await action_cb():
  File "/home/VMmanager/.local/lib/python3.8/site-packages/telegram/ext/_updater.py", line 335, in polling_action_cb
    raise exc
  File "/home/VMmanager/.local/lib/python3.8/site-packages/telegram/ext/_updater.py", line 320, in polling_action_cb
    updates = await self.bot.get_updates(
  File "/home/VMmanager/.local/lib/python3.8/site-packages/telegram/ext/_extbot.py", line 524, in get_updates
    updates = await super().get_updates(
  File "/home/VMmanager/.local/lib/python3.8/site-packages/telegram/_bot.py", line 331, in decorator
    result = await func(*args, **kwargs)  # skipcq: PYL-E1102
  File "/home/VMmanager/.local/lib/python3.8/site-packages/telegram/_bot.py", line 3510, in get_updates
    await self._post(
  File "/home/VMmanager/.local/lib/python3.8/site-packages/telegram/_bot.py", line 419, in _post
    return await self._do_post(
  File "/home/VMmanager/.local/lib/python3.8/site-packages/telegram/ext/_extbot.py", line 306, in _do_post
    return await super()._do_post(
  File "/home/VMmanager/.local/lib/python3.8/site-packages/telegram/_bot.py", line 450, in _do_post
    return await request.post(
  File "/home/VMmanager/.local/lib/python3.8/site-packages/telegram/request/_baserequest.py", line 165, in post
    result = await self._request_wrapper(
  File "/home/VMmanager/.local/lib/python3.8/site-packages/telegram/request/_baserequest.py", line 288, in _request_wrapper
    raise exc
  File "/home/VMmanager/.local/lib/python3.8/site-packages/telegram/request/_baserequest.py", line 274, in _request_wrapper
    code, payload = await self.do_request(
  File "/home/VMmanager/.local/lib/python3.8/site-packages/telegram/request/_httpxrequest.py", line 223, in do_request
    raise NetworkError(f"httpx.{err.__class__.__name__}: {err}") from err
telegram.error.NetworkError: httpx.LocalProtocolError: Invalid input ConnectionInputs.SEND_HEADERS in state ConnectionState.CLOSED
2023-03-25 20:15:48,021 - telegram.ext._updater - ERROR - Error while getting Updates: httpx.LocalProtocolError: Invalid input ConnectionInputs.SEND_HEADERS in state ConnectionState.CLOSED
2023-03-25 20:15:48,021 - telegram.ext._application - ERROR - No error handlers are registered, logging exception.
Traceback (most recent call last):
  File "/home/VMmanager/.local/lib/python3.8/site-packages/h2/connection.py", line 224, in process_input
    func, target_state = self._transitions[(self.state, input_)]
KeyError: (<ConnectionState.CLOSED: 3>, <ConnectionInputs.SEND_HEADERS: 0>)

During handling of the above exception, another exception occurred:

Traceback (most recent call last):
  File "/home/VMmanager/.local/lib/python3.8/site-packages/httpcore/_async/http2.py", line 106, in handle_async_request
    await self._send_request_headers(request=request, stream_id=stream_id)
  File "/home/VMmanager/.local/lib/python3.8/site-packages/httpcore/_async/http2.py", line 203, in _send_request_headers
    self._h2_state.send_headers(stream_id, headers, end_stream=end_stream)
  File "/home/VMmanager/.local/lib/python3.8/site-packages/h2/connection.py", line 766, in send_headers
    self.state_machine.process_input(ConnectionInputs.SEND_HEADERS)
  File "/home/VMmanager/.local/lib/python3.8/site-packages/h2/connection.py", line 228, in process_input
    raise ProtocolError(
h2.exceptions.ProtocolError: Invalid input ConnectionInputs.SEND_HEADERS in state ConnectionState.CLOSED

During handling of the above exception, another exception occurred:

Traceback (most recent call last):
  File "/home/VMmanager/.local/lib/python3.8/site-packages/httpx/_transports/default.py", line 60, in map_httpcore_exceptions
    yield
  File "/home/VMmanager/.local/lib/python3.8/site-packages/httpx/_transports/default.py", line 353, in handle_async_request
    resp = await self._pool.handle_async_request(req)
  File "/home/VMmanager/.local/lib/python3.8/site-packages/httpcore/_async/connection_pool.py", line 253, in handle_async_request
    raise exc
  File "/home/VMmanager/.local/lib/python3.8/site-packages/httpcore/_async/connection_pool.py", line 237, in handle_async_request
    response = await connection.handle_async_request(request)
  File "/home/VMmanager/.local/lib/python3.8/site-packages/httpcore/_async/connection.py", line 90, in handle_async_request
    return await self._connection.handle_async_request(request)
  File "/home/VMmanager/.local/lib/python3.8/site-packages/httpcore/_async/http2.py", line 142, in handle_async_request
    raise LocalProtocolError(exc)  # pragma: nocover
httpcore.LocalProtocolError: Invalid input ConnectionInputs.SEND_HEADERS in state ConnectionState.CLOSED

The above exception was the direct cause of the following exception:

Traceback (most recent call last):
  File "/home/VMmanager/.local/lib/python3.8/site-packages/telegram/request/_httpxrequest.py", line 199, in do_request
    res = await self._client.request(
  File "/home/VMmanager/.local/lib/python3.8/site-packages/httpx/_client.py", line 1533, in request
    return await self.send(request, auth=auth, follow_redirects=follow_redirects)
  File "/home/VMmanager/.local/lib/python3.8/site-packages/httpx/_client.py", line 1620, in send
    response = await self._send_handling_auth(
  File "/home/VMmanager/.local/lib/python3.8/site-packages/httpx/_client.py", line 1648, in _send_handling_auth
    response = await self._send_handling_redirects(
  File "/home/VMmanager/.local/lib/python3.8/site-packages/httpx/_client.py", line 1685, in _send_handling_redirects
    response = await self._send_single_request(request)
  File "/home/VMmanager/.local/lib/python3.8/site-packages/httpx/_client.py", line 1722, in _send_single_request
    response = await transport.handle_async_request(request)
  File "/home/VMmanager/.local/lib/python3.8/site-packages/httpx/_transports/default.py", line 353, in handle_async_request
    resp = await self._pool.handle_async_request(req)
  File "/usr/lib/python3.8/contextlib.py", line 131, in __exit__
    self.gen.throw(type, value, traceback)
  File "/home/VMmanager/.local/lib/python3.8/site-packages/httpx/_transports/default.py", line 77, in map_httpcore_exceptions
    raise mapped_exc(message) from exc
httpx.LocalProtocolError: Invalid input ConnectionInputs.SEND_HEADERS in state ConnectionState.CLOSED

The above exception was the direct cause of the following exception:

Traceback (most recent call last):
  File "/home/VMmanager/.local/lib/python3.8/site-packages/telegram/ext/_updater.py", line 607, in _network_loop_retry
    if not await action_cb():
  File "/home/VMmanager/.local/lib/python3.8/site-packages/telegram/ext/_updater.py", line 335, in polling_action_cb
    raise exc
  File "/home/VMmanager/.local/lib/python3.8/site-packages/telegram/ext/_updater.py", line 320, in polling_action_cb
    updates = await self.bot.get_updates(
  File "/home/VMmanager/.local/lib/python3.8/site-packages/telegram/ext/_extbot.py", line 524, in get_updates
    updates = await super().get_updates(
  File "/home/VMmanager/.local/lib/python3.8/site-packages/telegram/_bot.py", line 331, in decorator
    result = await func(*args, **kwargs)  # skipcq: PYL-E1102
  File "/home/VMmanager/.local/lib/python3.8/site-packages/telegram/_bot.py", line 3510, in get_updates
    await self._post(
  File "/home/VMmanager/.local/lib/python3.8/site-packages/telegram/_bot.py", line 419, in _post
    return await self._do_post(
  File "/home/VMmanager/.local/lib/python3.8/site-packages/telegram/ext/_extbot.py", line 306, in _do_post
    return await super()._do_post(
  File "/home/VMmanager/.local/lib/python3.8/site-packages/telegram/_bot.py", line 450, in _do_post
    return await request.post(
  File "/home/VMmanager/.local/lib/python3.8/site-packages/telegram/request/_baserequest.py", line 165, in post
    result = await self._request_wrapper(
  File "/home/VMmanager/.local/lib/python3.8/site-packages/telegram/request/_baserequest.py", line 288, in _request_wrapper
    raise exc
  File "/home/VMmanager/.local/lib/python3.8/site-packages/telegram/request/_baserequest.py", line 274, in _request_wrapper
    code, payload = await self.do_request(
  File "/home/VMmanager/.local/lib/python3.8/site-packages/telegram/request/_httpxrequest.py", line 223, in do_request
    raise NetworkError(f"httpx.{err.__class__.__name__}: {err}") from err
telegram.error.NetworkError: httpx.LocalProtocolError: Invalid input ConnectionInputs.SEND_HEADERS in state ConnectionState.CLOSED
2023-03-25 20:15:51,403 - telegram.ext._updater - ERROR - Error while getting Updates: httpx.LocalProtocolError: Invalid input ConnectionInputs.SEND_HEADERS in state ConnectionState.CLOSED
2023-03-25 20:15:51,403 - telegram.ext._application - ERROR - No error handlers are registered, logging exception.
Traceback (most recent call last):
  File "/home/VMmanager/.local/lib/python3.8/site-packages/h2/connection.py", line 224, in process_input
    func, target_state = self._transitions[(self.state, input_)]
KeyError: (<ConnectionState.CLOSED: 3>, <ConnectionInputs.SEND_HEADERS: 0>)

During handling of the above exception, another exception occurred:

Traceback (most recent call last):
  File "/home/VMmanager/.local/lib/python3.8/site-packages/httpcore/_async/http2.py", line 106, in handle_async_request
    await self._send_request_headers(request=request, stream_id=stream_id)
  File "/home/VMmanager/.local/lib/python3.8/site-packages/httpcore/_async/http2.py", line 203, in _send_request_headers
    self._h2_state.send_headers(stream_id, headers, end_stream=end_stream)
  File "/home/VMmanager/.local/lib/python3.8/site-packages/h2/connection.py", line 766, in send_headers
    self.state_machine.process_input(ConnectionInputs.SEND_HEADERS)
  File "/home/VMmanager/.local/lib/python3.8/site-packages/h2/connection.py", line 228, in process_input
    raise ProtocolError(
h2.exceptions.ProtocolError: Invalid input ConnectionInputs.SEND_HEADERS in state ConnectionState.CLOSED

During handling of the above exception, another exception occurred:

Traceback (most recent call last):
  File "/home/VMmanager/.local/lib/python3.8/site-packages/httpx/_transports/default.py", line 60, in map_httpcore_exceptions
    yield
  File "/home/VMmanager/.local/lib/python3.8/site-packages/httpx/_transports/default.py", line 353, in handle_async_request
    resp = await self._pool.handle_async_request(req)
  File "/home/VMmanager/.local/lib/python3.8/site-packages/httpcore/_async/connection_pool.py", line 253, in handle_async_request
    raise exc
  File "/home/VMmanager/.local/lib/python3.8/site-packages/httpcore/_async/connection_pool.py", line 237, in handle_async_request
    response = await connection.handle_async_request(request)
  File "/home/VMmanager/.local/lib/python3.8/site-packages/httpcore/_async/connection.py", line 90, in handle_async_request
    return await self._connection.handle_async_request(request)
  File "/home/VMmanager/.local/lib/python3.8/site-packages/httpcore/_async/http2.py", line 142, in handle_async_request
    raise LocalProtocolError(exc)  # pragma: nocover
httpcore.LocalProtocolError: Invalid input ConnectionInputs.SEND_HEADERS in state ConnectionState.CLOSED

The above exception was the direct cause of the following exception:

Traceback (most recent call last):
  File "/home/VMmanager/.local/lib/python3.8/site-packages/telegram/request/_httpxrequest.py", line 199, in do_request
    res = await self._client.request(
  File "/home/VMmanager/.local/lib/python3.8/site-packages/httpx/_client.py", line 1533, in request
    return await self.send(request, auth=auth, follow_redirects=follow_redirects)
  File "/home/VMmanager/.local/lib/python3.8/site-packages/httpx/_client.py", line 1620, in send
    response = await self._send_handling_auth(
  File "/home/VMmanager/.local/lib/python3.8/site-packages/httpx/_client.py", line 1648, in _send_handling_auth
    response = await self._send_handling_redirects(
  File "/home/VMmanager/.local/lib/python3.8/site-packages/httpx/_client.py", line 1685, in _send_handling_redirects
    response = await self._send_single_request(request)
  File "/home/VMmanager/.local/lib/python3.8/site-packages/httpx/_client.py", line 1722, in _send_single_request
    response = await transport.handle_async_request(request)
  File "/home/VMmanager/.local/lib/python3.8/site-packages/httpx/_transports/default.py", line 353, in handle_async_request
    resp = await self._pool.handle_async_request(req)
  File "/usr/lib/python3.8/contextlib.py", line 131, in __exit__
    self.gen.throw(type, value, traceback)
  File "/home/VMmanager/.local/lib/python3.8/site-packages/httpx/_transports/default.py", line 77, in map_httpcore_exceptions
    raise mapped_exc(message) from exc
httpx.LocalProtocolError: Invalid input ConnectionInputs.SEND_HEADERS in state ConnectionState.CLOSED

The above exception was the direct cause of the following exception:

Traceback (most recent call last):
  File "/home/VMmanager/.local/lib/python3.8/site-packages/telegram/ext/_updater.py", line 607, in _network_loop_retry
    if not await action_cb():
  File "/home/VMmanager/.local/lib/python3.8/site-packages/telegram/ext/_updater.py", line 335, in polling_action_cb
    raise exc
  File "/home/VMmanager/.local/lib/python3.8/site-packages/telegram/ext/_updater.py", line 320, in polling_action_cb
    updates = await self.bot.get_updates(
  File "/home/VMmanager/.local/lib/python3.8/site-packages/telegram/ext/_extbot.py", line 524, in get_updates
    updates = await super().get_updates(
  File "/home/VMmanager/.local/lib/python3.8/site-packages/telegram/_bot.py", line 331, in decorator
    result = await func(*args, **kwargs)  # skipcq: PYL-E1102
  File "/home/VMmanager/.local/lib/python3.8/site-packages/telegram/_bot.py", line 3510, in get_updates
    await self._post(
  File "/home/VMmanager/.local/lib/python3.8/site-packages/telegram/_bot.py", line 419, in _post
    return await self._do_post(
  File "/home/VMmanager/.local/lib/python3.8/site-packages/telegram/ext/_extbot.py", line 306, in _do_post
    return await super()._do_post(
  File "/home/VMmanager/.local/lib/python3.8/site-packages/telegram/_bot.py", line 450, in _do_post
    return await request.post(
  File "/home/VMmanager/.local/lib/python3.8/site-packages/telegram/request/_baserequest.py", line 165, in post
    result = await self._request_wrapper(
  File "/home/VMmanager/.local/lib/python3.8/site-packages/telegram/request/_baserequest.py", line 288, in _request_wrapper
    raise exc
  File "/home/VMmanager/.local/lib/python3.8/site-packages/telegram/request/_baserequest.py", line 274, in _request_wrapper
    code, payload = await self.do_request(
  File "/home/VMmanager/.local/lib/python3.8/site-packages/telegram/request/_httpxrequest.py", line 223, in do_request
    raise NetworkError(f"httpx.{err.__class__.__name__}: {err}") from err
telegram.error.NetworkError: httpx.LocalProtocolError: Invalid input ConnectionInputs.SEND_HEADERS in state ConnectionState.CLOSED
